Workbook

Sheet GRI_v8
A1: Section | B1: Criterion | C1: Score (1-10)
A2: Product & Demand | B2: Критичность боли | C2: 9
A3: Product & Demand | B3: Что клиент теряет каждый месяц, если не решит проблему? Насколько он эту критичность осознает | C3: 9
A4: Product & Demand | B4: Стиль поиска решения | C4: 3
A5: Product & Demand | B5: Потенциал высокого чека | C5: 5
A6: Product & Demand | B6: Потенциал повторных покупок | C6: 4
A7: Product & Demand | B7: Потенциал платёжеспособного сегмента | C7: 6
A8: Trust & Positioning | B8: Доверие с первого контакта | C8: 8
A9: Trust & Positioning | B9: Доказательства результата | C9: 9
A10: Trust & Positioning | B10: Социальное доказательство | C10: 2
A11: Trust & Positioning | B11: Понятность вашего решения | C11: 3
A12: Trust & Positioning | B12: Достаточность информации о Вас в сети | C12: 4
A13: Trust & Positioning | B13: Отстройка от конкурентов | C13: 5
... A49: Founder Readiness | B49: Уровень цифровизации | C49: 6

Sheet GRI_v8_2
A1: Section | B1: Criterion | C1: Score (1-10)
A2: Product & Demand | B2: Критичность боли | C2: ='GRI_2 (для примера, так надо сд'!C3 -> 8
A3: Product & Demand | B3: Что клиент теряет каждый месяц, если не решит проблему? Насколько он эту критичность осознает | C3: ='GRI_2 (для примера, так надо сд'!C6 -> 4
A4: Product & Demand | B4: Стиль поиска решения | C4: ='GRI_2 (для примера, так надо сд'!C12 -> 1
A5: Product & Demand | B5: Потенциал высокого чека | C5: ='GRI_2 (для примера, так надо сд'!C15 -> 10
A6: Product & Demand | B6: Потенциал повторных покупок | C6: ='GRI_2 (для примера, так надо сд'!C18 -> 2
A7: Product & Demand | B7: Потенциал платёжеспособного сегмента | C7: ='GRI_2 (для примера, так надо сд'!C24 -> 6
A8: Product & Demand | B8: ='GRI_2 (для примера, так надо сд'!A21 -> Апселлы и кросселлы | C8: ='GRI_2 (для примера, так надо сд'!C21 -> 3
A9: Product & Demand | B9: ='GRI_2 (для примера, так надо сд'!A24 -> Платёжеспособный сегмент | C9: ='GRI_2 (для примера, так надо сд'!C24 -> 6
A10: Product & Demand | B10: ='GRI_2 (для примера, так надо сд'!A27 -> Динамика рынка | C10: ='GRI_2 (для примера, так надо сд'!C27 -> 4
A11: Product & Demand | B11: ='GRI_2 (для примера, так надо сд'!A30 -> Быстрота решения о покупке | C11: ='GRI_2 (для примера, так надо сд'!C30 -> 3
A12: Trust & Positioning | B12: Доверие с первого контакта | C12: 8
A13: Trust & Positioning | B13: Доказательства результата | C13: 9
A14: Trust & Positioning | B14: Социальное доказательство | C14: 2
A15: Trust & Positioning | B15: Понятность вашего решения | C15: 3
A16: Trust & Positioning | B16: Достаточность информации о Вас в сети | C16: 4
A17: Trust & Positioning | B17: Отстройка от конкурентов | C17: 5
A18: Business Model | B18: Подписочная модель | C18: 6
A19: Business Model | B19: Дополнительные продажи (апселлы) | C19: 7
A20: Business Model | B20: Партнёрские каналы | C20: 7
A21: Business Model | B21: Географическое масштабирование | C21: 8
A22: Business Model | B22: Эффективность стоимости привлечения | C22: 9
A23: Cash Stability | B23: Возможность внедрить депозит (предоплату) | C23: 8
... A25: Cash Stability | B25: Окупаемость стоимости привлечения (CAC Payback) | C25: 2
A26: Cash Stability | B26: Влияние депозита / рассрочки на LTV
A27: Cash Stability | B27: Прозрачность финансового потока
A28: Cash Stability | B28: Скорость оборота денег
A29: Cash Stability | B29: Финансовая устойчивость модели
A30: Operations | B30: Повторяемость процесса | C30: 4
A31: Operations | B31: Стандарты выполнения | C31: 1
A32: Operations | B32: Готовые модули для тиражирования | C32: 3
A33: Operations | B33: Риски при масштабировании / для партнёров | C33: 4
A34: Operations | B34: Метрики результата команды | C34: 1
A35: Operations | B35: Предсказуемость результата | C35: 1
A36: Operations | B36: Контроль качества | C36: 1
A37: Team | B37: Укомплектованность под $2M | C37: 2
A38: Team | B38: Цифровизация | C38: 2
A39: Team | B39: Культура изменений | C39: 2
A40: Team | B40: Прописанные ЦКП и чек-листы | C40: 2
A41: Team | B41: Исполнительная дисциплина | C41: 8
...

Sheet AutoReport_2
A1: Автоматический отчет GRI
A2: Блок | B2: Средний балл (0–10) | C2: Краткая интерпретация
A3: Product & Demand | B3: =AVERAGEIF(GRI_v8_2!$A:$A,"Product & Demand",GRI_v8_2!$C:$C) -> 4.7 | C3: =IF(B3<4,"Критический блок, без доработки масштабирование невозможно.", IF(B3<6,"Слабое место, требует приоритетной доработки перед ростом.", IF(B3<8,"Достаточный уровень, но есть зоны для усиления.", "Сильная сторона, может быть опорой для масштабирования."))) -> Слабое место, требует приоритетной доработки перед ростом.
A4: Trust & Positioning | B4: =AVERAGEIF(GRI_v8_2!$A:$A,"Trust & Positioning",GRI_v8_2!$C:$C) -> 5.1666667 | C4: =IF(B4<4,"Критический блок, без доработки масштабирование невозможно.", IF(B4<6,"Слабое место, требует приоритетной доработки перед ростом.", IF(B4<8,"Достаточный уровень, но есть зоны для усиления.", "Сильная сторона, может быть опорой для масштабирования."))) -> Слабое место, требует приоритетной доработки перед ростом.
A5: Business Model | B5: =AVERAGEIF(GRI_v8!$A:$A,"Business Model",GRI_v8!$C:$C) -> 7.4 | C5: =IF(B5<4,"Критический блок, без доработки масштабирование невозможно.", IF(B5<6,"Слабое место, требует приоритетной доработки перед ростом.", IF(B5<8,"Достаточный уровень, но есть зоны для усиления.", "Сильная сторона, может быть опорой для масштабирования."))) -> Достаточный уровень, но есть зоны для усиления.
A6: Cash Stability | B6: =AVERAGEIF(GRI_v8!$A:$A,"Cash Stability",GRI_v8!$C:$C) -> 5 | C6: =IF(B6<4,"Критический блок, без доработки масштабирование невозможно.", IF(B6<6,"Слабое место, требует приоритетной доработки перед ростом.", IF(B6<8,"Достаточный уровень, но есть зоны для усиления.", "Сильная сторона, может быть опорой для масштабирования."))) -> Слабое место, требует приоритетной доработки перед ростом.
A7: Operations | B7: =AVERAGEIF(GRI_v8!$A:$A,"Operations",GRI_v8!$C:$C) -> 2.1428571 | C7: =IF(B7<4,"Критический блок, без доработки масштабирование невозможно.", IF(B7<6,"Слабое место, требует приоритетной доработки перед ростом.", IF(B7<8,"Достаточный уровень, но есть зоны для усиления.", "Сильная сторона, может быть опорой для масштабирования."))) -> Критический блок, без доработки масштабирование невозможно.
A8: Team | B8: =AVERAGEIF(GRI_v8!$A:$A,"Team",GRI_v8!$C:$C) -> 2.5454545 | C8: =IF(B8<4,"Критический блок, без доработки масштабирование невозможно.", IF(B8<6,"Слабое место, требует приоритетной доработки перед ростом.", IF(B8<8,"Достаточный уровень, но есть зоны для усиления.", "Сильная сторона, может быть опорой для масштабирования."))) -> Критический блок, без доработки масштабирование невозможно.
A9: Founder Readiness | B9: =AVERAGEIF(GRI_v8!$A:$A,"Founder Readiness",GRI_v8!$C:$C) -> 6.7 | C9: =IF(B9<4,"Критический блок, без доработки масштабирование невозможно.", IF(B9<6,"Слабое место, требует приоритетной доработки перед ростом.", IF(B9<8,"Достаточный уровень, но есть зоны для усиления.", "Сильная сторона, может быть опорой для масштабирования."))) -> Достаточный уровень, но есть зоны для усиления.
A12: Итоговый GRI | B12: =B3*0.25 + B4*0.05 + B5*0.1 + B6*0.05 + B7*0.15 + B8*0.2 + B9*0.2 -> 4.5938528
A14: Интерпретация результата | B14: =IF(B12<4,"Низкая готовность к масштабированию. Масштаб запускать нельзя, требуется глубокий пилот и перестройка модели.",IF(B12<6,"Средняя готовность. Есть потенциал, но высокий риск провала при росте. Нужен пилот и доработка ключевых блоков.",IF(B12<8,"Хорошая основа. Можно готовиться к масштабированию после усиления слабых зон (команда, операции, экономика).","Высокая готовность. При системной работе продукт может выйти на $2M за 12–18 месяцев."))) -> Средняя готовность. Есть потенциал, но высокий риск провала при росте. Нужен пилот и доработка ключевых блоков.
A16: Рекомендации на ближайшие 30 дней
A17: - Определить 2–3 самых слабых блока по GRI и сфокусировать усилия на них.
A18: - Перепроверить продуктовую ценность и воронку: лид → диалог → предложение → сделка.
A19: - Настроить базовый набор метрик: лиды, конверсия, выручка, стоимость привлечения.
A20: - Перераспределить нагрузку с собственника на команду через роли, ЦКП и регламенты.
A21: - Подготовить и запустить пилотный период 21–30 дней с чёткими целями по деньгам и метрикам.
A23: Потенциал выхода на $2M за 12–18 месяцев | B23: =IF( B12<4, "В текущей конфигурации вероятность выхода на $2M низкая. Нужна серьёзная перестройка продукта, команды и процессов.", IF( B12<6, "При доработке продукта, команды и операционной системы возможно движение к $2M за 2–3 года.", IF( B12<8, "Есть шанс выйти на $2M за 18–24 месяца при усилении слабых блоков и сохранении дисциплины.", "Есть высокий шанс достижения $2M за 12–18 месяцев при системной работе и контроле ключевых метрик." ) ) ) -> При доработке продукта, команды и операционной системы возможно движение к $2M за 2–3 года.
A26: Анализ проведён | B26: Марина Рахимжанова

Sheet GRI_2 (для примера, так надо сд
A2: Product & Demand | B2: Что измеряем | C2: Оцените уровень | D2: Оценка ответа | E2: Ответы | F2: Что нужно добавить | G2: Что бизнес теряет при низкой оценке
A3: Критичность боли | B3: Насколько клиент ощущает проблему как срочную, опасную или дорогостоящую | C3: 8 | D3: Уровень 1–3 | E3: Клиент не считает проблему серьёзной. Верит, что «само рассосётся». | F3: Диагностика последствий, формулировки боли, подкреплённые цифрами | G3: Длинный цикл сделки ×2–×4, низкий чек, слабый спрос
D4: Уровень 4–7 | E4: Клиент понимает проблему, но откладывает решение, выбирает «подешевле».
D5: Уровень 8–10 | E5: Клиент ощущает проблему как критичную (9–10), хочет решить сейчас, а не «когда-нибудь».
A6: Потери клиента | B6: Деньги, время, риски, которые клиент теряет ежемесячно | C6: 4 | D6: Уровень 1–3 | E6: Потери не осознаются, считаются «нормой рынка». | F6: Оцифровать потери, усилить последствиями | G6: Клиент не покупает — отсутствие мотивации, низкая ценность
D7: Уровень 4–7 | E7: Клиент знает о потерях, но не считает их критичными.
D8: Уровень 8–10 | E8: Клиент ясно понимает: теряет 10–30% потенциала/выручки каждый месяц.
A9: Осознанность проблемы | B9: Понимает ли клиент, почему у него эта проблема | C9: 2 | D9: Уровень 1–3 | E9: «Так сложилось», виноваты рынок, команда, клиенты. | F9: Диагностические вопросы, объяснение причин | G9: Клиент винит обстоятельства → не покупает решения системного уровня
D10: Уровень 4–7 | E10: Понимает часть причин, но не видит целостной картины.
D11: Уровень 8–10 | E11: Понимает 80–100% причин и готов менять систему, а не латать симптомы.
A12: Активность поиска | B12: Насколько активно клиент ищет решение | C12: 1 | D12: Уровень 1–3 | E12: Не ищет, откладывает, живёт в режиме ожидания. | F12: Сформировать осознание боли 9–10, показать риск упущенной выгоды | G12: Медленный цикл сделки; падение спроса до 50%
D13: Уровень 4–7 | E13: Иногда мониторит варианты, сравнивает, но без действия.
D14: Уровень 8–10 | E14: Активно ищет, сравнивает, готов платить за результат.
A15: Потенциал высокого чека | B15: Готовность клиента платить больше за качественное решение | C15: 10 | D15: Уровень 1–3 | E15: Чек низкий, рынок чувствителен к цене. | F15: Упаковка ценности, премиум-опции | G15: Потолок выручки падает ×2–×10
D16: Уровень 4–7 | E16: Чек можно поднять, но нужны доказательства.
D17: Уровень 8–10 | E17: Чек можно увеличить ×2–×5 при той же аудитории.
A18: Повторные покупки | B18: Как часто клиент возвращается | C18: 2 | D18: Уровень 1–3 | E18: Одноразовая покупка. | F18: Модель подписки/репокупок | G18: Рост невозможен без повторяемости, высокая стоимость привлечения
D19: Уровень 4–7 | E19: Часть клиентов возвращается.
D20: Уровень 8–10 | E20: Клиент возвращается регулярно, LTV прогнозируем.
A21: Апселлы и кросселлы | B21: Сколько ещё клиент может купить | C21: 3 | D21: Уровень 1–3 | E21: Нет доп. продуктов. | F21: Создать продуктовую матрицу | G21: Потеря LTV, невозможность масштабирования прибыльно
D22: Уровень 4–7 | E22: Есть 1–2 доп. позиции.
D23: Уровень 8–10 | E23: Есть линейка, рост чека ×2–×4.
A24: Платёжеспособный сегмент | B24: Платит ли уже рынок за такие решения | C24: 6 | D24: Уровень 1–3 | E24: Рынок не платит. | F24: Сегментация, поиск ICP | G24: Если сегмент бедный — рост невозможен
D25: Уровень 4–7 | E25: Платит частично, бюджеты ограничены.
D26: Уровень 8–10 | E26: Рынок активно платит, бюджеты заложены.
A27: Динамика рынка | B27: Рынок растёт или сужается | C27: 4 | D27: Уровень 1–3 | E27: Падающий рынок. | F27: Анализ трендов, данные рынка | G27: Падающий рынок → нулевой потенциал для 2 млрд
D28: Уровень 4–7 | E28: Стабильный рынок.
D29: Уровень 8–10 | E29: Быстрорастущий рынок (×3–×5 за 3–5 лет).
A30: Быстрота решения о покупке | B30: Насколько быстро сегмент принимает решения | C30: 3 | D30: Уровень 1–3 | E30: Думают долго, откладывают. | F30: Уточнить ICP, сузить сегмент | G30: Цикл сделки ×2–×5 дольше
D31: Уровень 4–7 | E31: Размышляют, но с интересом.
D32: Уровень 8–10 | E32: Покупают за 24–72 часа.
A33: Уровень доверия к решению с первого контакта | B33: Насколько клиент верит, что вы решите проблему | C33: 1 | D33: Уровень 1–3 | E33: Недоверие, много сомнений. | F33: Кейс-стори, доказательства, соцдоказательства | G33: Снижение конверсии на 30–70%, длинный цикл сделки
D34: Уровень 4–7 | E34: Частично доверяет.
D35: Уровень 8–10 | E35: Уверен, что вы лучшее решение на рынке.
A37: Trust & Positioning | B37: Что измеряем | C37: Оцените уровень | D37: Оценка ответа | E37: Ответы | F37: Что нужно добавить | G37: Что бизнес теряет при низкой оценке
A38: Уровень доверия к решению с первого контакта | B38: Насколько быстро клиент чувствует уверенность в компании | C38: 5 | D38: Уровень 1–3 | E38: Сомнения, ощущение неопределённости | F38: Кейс-стори, доказательства, соцдоказательства | G38: Снижение конверсии на 30–70%, длинный цикл сделки
D39: Уровень 4–7 | E39: Есть базовое доверие, но много вопросов
D40: Уровень 8–10 | E40: Полное ощущение безопасности и надёжности
A41: Доказательства качества и результата (Proofs) | B41: Наличие кейсов, примеров, результатов | C41: 4 | D41: Уровень 1–3 | E41: Кейс отсутствуют или слабые | F41: Собирать кейсы, оформлять результаты, «до-после» | G41: До 50% клиентов не доходят до покупки из-за сомнений
D42: Уровень 4–7 | E42: Есть кейсы, но не системные
...

Sheet ALL_SCORES
A2: Блок | B2: Критерий | C2: Балл | D2: Ранг
A3: Product & Demand | B3: Критичность боли | C3: =GRI_v8_2!C2 -> 8 | D3: =_xlfn.RANK.EQ(C3,$C$2:$C$49,1)+COUNTIF($C$2:C3,C3)-1 -> 38
A4: Product & Demand | B4: Что клиент теряет каждый месяц, если не решит проблему? Насколько он эту критичность осознает | C4: =GRI_v8!C4 -> 3 | D4: =_xlfn.RANK.EQ(C4,$C$2:$C$49,1)+COUNTIF($C$2:C4,C4)-1 -> 17
A5: Product & Demand | B5: Стиль поиска решения | C5: =GRI_v8!C5 -> 5 | D5: =_xlfn.RANK.EQ(C5,$C$2:$C$49,1)+COUNTIF($C$2:C5,C5)-1 -> 24
A6: Product & Demand | B6: Потенциал высокого чека | C6: =GRI_v8!C6 -> 4 | D6: =_xlfn.RANK.EQ(C6,$C$2:$C$49,1)+COUNTIF($C$2:C6,C6)-1 -> 20
A7: Product & Demand | B7: Потенциал повторных покупок | C7: =GRI_v8!C7 -> 6 | D7: =_xlfn.RANK.EQ(C7,$C$2:$C$49,1)+COUNTIF($C$2:C7,C7)-1 -> 27
A8: Product & Demand | B8: Потенциал платёжеспособного сегмента | C8: =GRI_v8!C8 -> 8 | D8: =_xlfn.RANK.EQ(C8,$C$2:$C$49,1)+COUNTIF($C$2:C8,C8)-1 -> 39
A9: Trust & Positioning | B9: Доверие с первого контакта | C9: =GRI_v8!C9 -> 9 | D9: =_xlfn.RANK.EQ(C9,$C$2:$C$49,1)+COUNTIF($C$2:C9,C9)-1 -> 45
A10: Trust & Positioning | B10: Доказательства результата | C10: =GRI_v8!C10 -> 2 | D10: =_xlfn.RANK.EQ(C10,$C$2:$C$49,1)+COUNTIF($C$2:C10,C10)-1 -> 5
A11: Trust & Positioning | B11: Социальное доказательство | C11: =GRI_v8!C11 -> 3 | D11: =_xlfn.RANK.EQ(C11,$C$2:$C$49,1)+COUNTIF($C$2:C11,C11)-1 -> 18
A12: Trust & Positioning | B12: Понятность вашего решения | C12: =GRI_v8!C12 -> 4 | D12: =_xlfn.RANK.EQ(C12,$C$2:$C$49,1)+COUNTIF($C$2:C12,C12)-1 -> 21
A13: Trust & Positioning | B13: Достаточность информации о Вас в сети | C13: =GRI_v8!C13 -> 5 | D13: =_xlfn.RANK.EQ(C13,$C$2:$C$49,1)+COUNTIF($C$2:C13,C13)-1 -> 25
A14: Trust & Positioning | B14: Отстройка от конкурентов | C14: =GRI_v8!C14 -> 6 | D14: =_xlfn.RANK.EQ(C14,$C$2:$C$49,1)+COUNTIF($C$2:C14,C14)-1 -> 28
A15: Business Model | B15: Подписочная модель | C15: =GRI_v8!C15 -> 7 | D15: =_xlfn.RANK.EQ(C15,$C$2:$C$49,1)+COUNTIF($C$2:C15,C15)-1 -> 36
... A49: Founder Readiness | B49: Опыт управления 2М$ и более | C49: =GRI_v8!C49 -> 6 | D49: =_xlfn.RANK.EQ(C49,$C$2:$C$49,1)+COUNTIF($C$2:C49,C49)-1 -> 35
A50: Founder Readiness | B50: Уровень цифровизации | C50: =GRI_v8!C49 -> 6 | D50: =_xlfn.RANK.EQ(C50,$C$2:$C$49,1)+COUNTIF($C$2:C50,C50)-1 -> 36

Sheet GRI_full
A2: Product & Demand | B2: Что измеряем | D2: Оценка | E2: Уровень 1–3 | F2: Уровень 4–7 | G2: Уровень 8–10 | H2: Что нужно добавить | I2: Что бизнес теряет при низкой оценке
A3: 1. Критичность боли | B3: Насколько клиент ощущает проблему как срочную, опасную или дорогостоящую | C3: Уровень 1–3 | E3: Клиент не считает проблему серьёзной, можно «потерпеть» | H3: Диагностика последствий, формулировки боли, подкреплённые цифрами | I3: Длинный цикл сделки ×2–×4, низкий чек, слабый спрос
C4: Уровень 4–7 | E4: Клиент понимает проблему, но откладывает решение
C5: Уровень 8–10 | E5: Клиент ощущает проблему как критическую (9–10), хочет решить сейчас
A6: 2. Потери клиента | B6: Деньги, время, риски, которые клиент теряет ежемесячно | C6: Уровень 1–4 | E6: Потери не осознаются | H6: Оцифровать потери, усилить последствиями | I6: Клиент не покупает — отсутствие мотивации, низкая ценность
C7: Уровень 4–8 | E7: Клиент знает о потерях, но не считает их критичными
C8: Уровень 8–11 | E8: Клиент понимает, что каждый месяц теряет 10–30% потенциала/выручки
A9: 3. Осознанность проблемы | B9: Понимает ли клиент, почему у него эта проблема | C9: Уровень 1–5 | E9: Клиент считает, что «просто так вышло» | H9: Диагностические вопросы, объяснение причин | I9: Клиент винит обстоятельства → не покупает решения системного уровня
C10: Уровень 4–9 | E10: Понимает часть причин
C11: Уровень 8–12 | E11: Понимает 80–100% причин и готов менять систему
A12: 4. Активность поиска | B12: Насколько активно клиент ищет решение | C12: Уровень 1–6 | E12: Клиент не ищет решения, откладывает | H12: Сформировать осознание боли 9–10, показать риск упущенной выгоды | I12: Медленный цикл сделки; падение спроса до 50%
C13: Уровень 4–10 | E13: Иногда мониторит варианты
C14: Уровень 8–13 | E14: Активно ищет, сравнивает, готов платить
A15: 5. Потенциал высокого чека | B15: Готовность клиента платить больше за качественное решение | C15: Уровень 1–7 | E15: Чек низкий, рынок чувствителен к цене | H15: Упаковка ценности, премиум-опции | I15: Потолок выручки падает ×2–×10
C16: Уровень 4–11 | E16: Есть возможность повысить, но нужны доказательства
C17: Уровень 8–14 | E17: Чек можно увеличить ×2–×5 при той же аудитории
A18: 6. Повторные покупки | B18: Как часто клиент возвращается | C18: Уровень 1–8 | E18: Одноразовая покупка | H18: Модель подписки/репокупок | I18: Рост невозможен без повторяемости, высокая стоимость привлечения
C19: Уровень 4–12 | E19: Часть клиентов возвращается
C20: Уровень 8–15 | E20: Клиент возвращается регулярно, LTV предсказуем
A21: 7. Апселлы и кросселлы | B21: Сколько ещё клиент может купить | C21: Уровень 1–9 | E21: Нет дополнительных продуктов | H21: Создать продуктовую матрицу | I21: Потеря LTV, невозможность масштабирования прибыльно
C22: Уровень 4–13 | E22: Есть 1–2 позиции
C23: Уровень 8–16 | E23: Есть линейка, позволяющая увеличить чек ×2–×4
A24: 8. Платёжеспособный сегмент | B24: Платит ли рынок за такие решения | C24: Уровень 1–10 | E24: Рынок не платит | F24: Платит частично | G24: Рынок активно платит, есть бюджеты | H24: Сегментация, поиск ICP | I24: Если сегмент бедный — рост невозможен
C25: Уровень 4–14 | E25: Платит частично
C26: Уровень 8–17 | E26: Рынок активно платит, есть бюджеты
A27: 9. Динамика рынка | B27: Рынок растёт или сужается | C27: Уровень 1–11 | E27: Падающий рынок | F27: Стабильный | G27: Быстрорастущий (рост ×10 в 3–5 лет) | H27: Анализ трендов, данные рынка | I27: Падающий рынок → нулевой потенциал для 2 млрд
C28: Уровень 4–15 | E28: Стабильный
C29: Уровень 8–18 | E29: Быстрорастущий (рост ×10 в 3–5 лет)
A30: 10. Быстрота решения о покупке | B30: Насколько быстро сегмент принимает решения | C30: Уровень 1–12 | E30: Берут долго, много размышляют | F30: Размышляют, но с интересом | G30: Платят быстро — за 24–72 часа | H30: Уточнить ICP, сузить сегмент | I30: Цикл сделки ×2–×5 дольше
C31: Уровень 4–16 | E31: Размышляют, но с интересом
C32: Уровень 8–19 | E32: Платят быстро — за 24–72 часа
A33: 11. Уровень доверия к решению с первого контакта | B33: Насколько клиент верит, что вы решите проблему | C33: Уровень 1–12 | E33: Недоверие, много сомнений | F33: Частично доверяет | G33: Уверен, что вы — лучшее решение на рынке | H33: Кейс-стори, доказательства, соцдоказательства | I33: Снижение конверсии на 30–70%, длинный цикл сделки
C34: Уровень 4–16 | E34: Частично доверяет
C35: Уровень 8–19 | E35: Уверен, что вы — лучшее решение на рынке
A38: Trust & Positioning | B38: Что измеряем | E38: Уровень 1–3 | F38: Уровень 4–7 | G38: Уровень 8–10 | H38: Что нужно добавить | I38: Что бизнес теряет при низкой оценке
A39: 1. Доверие с первого контакта | B39: Насколько быстро клиент чувствует уверенность в компании | E39: Сомнения, ощущение неопределённости | F39: Есть базовое доверие, но много вопросов | G39: Полное ощущение безопасности и надёжности | H39: Чёткое позиционирование, профессиональный визуал, структурная подача | I39: Конверсия падает на 30–60%, цикл сделки удлиняется ×2–×4
A40: 2. Доказательства качества и результата (Proofs) | B40: Наличие кейсов, примеров, результатов | E40: Кейс отсутствуют или слабые | F40: Есть кейсы, но не системные | G40: Сильные, структурные кейсы, цифры, стабильные результаты | H40: Собирать кейсы, оформлять результаты, «до-после» | I40: До 50% клиентов не доходят до покупки из-за сомнений
A41: 3. Социальное доказательство (Social Proof) | B41: Отзывы, рекомендации, публичные упоминания | E41: Нет отзывов, нет подтверждений | F41: Есть, но мало и не оформлено | G41: Много отзывов, видео, рекомендации, упоминания | H41: Собирать отзывы, публиковать социальные сигналы | I41: Потеря 40–70% доверия, особенно при высоком чеке
A42: 4. Понятность решения (Clarity of Value) | B42: Понимает ли клиент, что вы делаете и как это улучшит его жизнь | E42: Не понимает, что вы продаёте | F42: Понимает частично | G42: Понимает сразу, без вопросов | H42: Ценностное предложение, чёткие формулировки, примеры | I42: До 80% клиентов не покупают то, что не понимают
A43: 5. Доступность информации о Вас | B43: Насколько легко найти информацию о компании | E43: Ничего не понятно, мало информации | F43: Информация есть, но не структурирована | G43: Понятно кто вы, что делаете, кто клиенты, какие результаты | H43: Сайты, профили, кейсы, публичность | I43: Недоверие → потеря до 50% конверсии
...

Sheet TOP_5_LIMITS
A1: Приоритет | B1: Ограничение | C1: Блок | D1: Балл
A2: 1 | B2: {=INDEX(ALL_SCORES!B:B, MATCH(1, ALL_SCORES!D:D, 0))} -> Повторяемость процесса | C2: {=INDEX(ALL_SCORES!A:A, MATCH(1, ALL_SCORES!D:D, 0))} -> Operations | D2: {=INDEX(ALL_SCORES!C:C, MATCH(1, ALL_SCORES!D:D, 0))} -> 1
A3: 2 | B3: {=INDEX(ALL_SCORES!B:B, MATCH(2, ALL_SCORES!D:D, 0))} -> Риски при масштабировании / для партнёров | C3: {=INDEX(ALL_SCORES!A:A, MATCH(2, ALL_SCORES!D:D, 0))} -> Operations | D3: {=INDEX(ALL_SCORES!C:C, MATCH(2, ALL_SCORES!D:D, 0))} -> 1
A4: 3 | B4: {=INDEX(ALL_SCORES!B:B, MATCH(3, ALL_SCORES!D:D, 0))} -> Метрики результата команды | C4: {=INDEX(ALL_SCORES!A:A, MATCH(3, ALL_SCORES!D:D, 0))} -> Operations | D4: {=INDEX(ALL_SCORES!C:C, MATCH(3, ALL_SCORES!D:D, 0))} -> 1
A5: 4 | B5: {=INDEX(ALL_SCORES!B:B, MATCH(4, ALL_SCORES!D:D, 0))} -> Предсказуемость результата | C5: {=INDEX(ALL_SCORES!A:A, MATCH(4, ALL_SCORES!D:D, 0))} -> Operations | D5: {=INDEX(ALL_SCORES!C:C, MATCH(4, ALL_SCORES!D:D, 0))} -> 1
A6: 5 | B6: {=INDEX(ALL_SCORES!B:B, MATCH(5, ALL_SCORES!D:D, 0))} -> Доказательства результата | C6: {=INDEX(ALL_SCORES!A:A, MATCH(5, ALL_SCORES!D:D, 0))} -> Trust & Positioning | D6: {=INDEX(ALL_SCORES!C:C, MATCH(5, ALL_SCORES!D:D, 0))} -> 2

Sheet ACTION_PLAN_90_DAYS
B1: Ограничение | C1: Фокус | D1: Действия: зафиксировать 1–3 ключевых решения и внедрить их в ежедневный ритм команды. | E1: Почему сейчас: это даст быстрый эффект и снизит потери при росте.
B2: =TOP_5_LIMITS!B2 -> Повторяемость процесса | C2: =IF(1<=2,"Деньги и скорость",IF(1<=4,"Система и команда","Масштабирование")) -> Деньги и скорость
B3: =TOP_5_LIMITS!B3 -> Риски при масштабировании / для партнёров | C3: =IF(2<=2,"Деньги и скорость",IF(2<=4,"Система и команда","Масштабирование")) -> Деньги и скорость
B4: =TOP_5_LIMITS!B4 -> Метрики результата команды | C4: =IF(3<=2,"Деньги и скорость",IF(3<=4,"Система и команда","Масштабирование")) -> Система и команда
B5: =TOP_5_LIMITS!B5 -> Предсказуемость результата | C5: =IF(4<=2,"Деньги и скорость",IF(4<=4,"Система и команда","Масштабирование")) -> Система и команда
B6: =TOP_5_LIMITS!B6 -> Доказательства результата | C6: =IF(5<=2,"Деньги и скорость",IF(5<=4,"Система и команда","Масштабирование")) -> Масштабирование

Sheet AutoReport
A1: Автоматический отчет GRI
A2: Блок | B2: Средний балл (0–10) | C2: Краткая интерпретация
A3: Product & Demand | B3: =AVERAGEIF(GRI_v8!$A:$A,"Product & Demand",GRI_v8!$C:$C) -> 6 | C3: =IF(B3<4,"Критический блок, без доработки масштабирование невозможно.", IF(B3<6,"Слабое место, требует приоритетной доработки перед ростом.", IF(B3<8,"Достаточный уровень, но есть зоны для усиления.", "Сильная сторона, может быть опорой для масштабирования."))) -> Достаточный уровень, но есть зоны для усиления.
A4: Trust & Positioning | B4: =AVERAGEIF(GRI_v8!$A:$A,"Trust & Positioning",GRI_v8!$C:$C) -> 5.1666667 | C4: =IF(B4<4,"Критический блок, без доработки масштабирование невозможно.", IF(B4<6,"Слабое место, требует приоритетной доработки перед ростом.", IF(B4<8,"Достаточный уровень, но есть зоны для усиления.", "Сильная сторона, может быть опорой для масштабирования."))) -> Слабое место, требует приоритетной доработки перед ростом.
A5: Business Model | B5: =AVERAGEIF(GRI_v8!$A:$A,"Business Model",GRI_v8!$C:$C) -> 7.4 | C5: =IF(B5<4,"Критический блок, без доработки масштабирование невозможно.", IF(B5<6,"Слабое место, требует приоритетной доработки перед ростом.", IF(B5<8,"Достаточный уровень, но есть зоны для усиления.", "Сильная сторона, может быть опорой для масштабирования."))) -> Достаточный уровень, но есть зоны для усиления.
A6: Deposit/Credit | B6: =AVERAGEIF(GRI_v8!$A:$A,"Deposit/Credit",GRI_v8!$C:$C) -> #DIV/0! | C6: =IF(B6<4,"Критический блок, без доработки масштабирование невозможно.", IF(B6<6,"Слабое место, требует приоритетной доработки перед ростом.", IF(B6<8,"Достаточный уровень, но есть зоны для усиления.", "Сильная сторона, может быть опорой для масштабирования."))) -> #DIV/0!
A7: Operations | B7: =AVERAGEIF(GRI_v8!$A:$A,"Operations",GRI_v8!$C:$C) -> 2.1428571 | C7: =IF(B7<4,"Критический блок, без доработки масштабирование невозможно.", IF(B7<6,"Слабое место, требует приоритетной доработки перед ростом.", IF(B7<8,"Достаточный уровень, но есть зоны для усиления.", "Сильная сторона, может быть опорой для масштабирования."))) -> Критический блок, без доработки масштабирование невозможно.
A8: Team | B8: =AVERAGEIF(GRI_v8!$A:$A,"Team",GRI_v8!$C:$C) -> 2.5454545 | C8: =IF(B8<4,"Критический блок, без доработки масштабирование невозможно.", IF(B8<6,"Слабое место, требует приоритетной доработки перед ростом.", IF(B8<8,"Достаточный уровень, но есть зоны для усиления.", "Сильная сторона, может быть опорой для масштабирования."))) -> Критический блок, без доработки масштабирование невозможно.
A9: Founder Readiness | B9: =AVERAGEIF(GRI_v8!$A:$A,"Founder Readiness",GRI_v8!$C:$C) -> 6.7 | C9: =IF(B9<4,"Критический блок, без доработки масштабирование невозможно.", IF(B9<6,"Слабое место, требует приоритетной доработки перед ростом.", IF(B9<8,"Достаточный уровень, но есть зоны для усиления.", "Сильная сторона, может быть опорой для масштабирования."))) -> Достаточный уровень, но есть зоны для усиления.
A12: Итоговый GRI | B12: =B3*0.25 + B4*0.05 + B5*0.1 + B6*0.05 + B7*0.15 + B8*0.2 + B9*0.2 -> #DIV/0!
A14: Интерпретация результата | B14: =IF(B12<4,"Низкая готовность к масштабированию. Масштаб запускать нельзя, требуется глубокий пилот и перестройка модели.",IF(B12<6,"Средняя готовность. Есть потенциал, но высокий риск провала при росте. Нужен пилот и доработка ключевых блоков.",IF(B12<8,"Хорошая основа. Можно готовиться к масштабированию после усиления слабых зон (команда, операции, экономика).","Высокая готовность. При системной работе продукт может выйти на $2M за 12–18 месяцев."))) -> #DIV/0!
A16: Рекомендации на ближайшие 30 дней
A17: - Определить 2–3 самых слабых блока по GRI и сфокусировать усилия на них.
A18: - Перепроверить продуктовую ценность и воронку: лид → диалог → предложение → сделка.
A19: - Настроить базовый набор метрик: лиды, конверсия, выручка, стоимость привлечения.
A20: - Перераспределить нагрузку с собственника на команду через роли, ЦКП и регламенты.
A21: - Подготовить и запустить пилотный период 21–30 дней с чёткими целями по деньгам и метрикам.
A23: Потенциал выхода на $2M за 12–18 месяцев | B23: =IF( B12<4, "В текущей конфигурации вероятность выхода на $2M низкая. Нужна серьёзная перестройка продукта, команды и процессов.", IF( B12<6, "При доработке продукта, команды и операционной системы возможно движение к $2M за 2–3 года.", IF( B12<8, "Есть шанс выйти на $2M за 18–24 месяца при усилении слабых блоков и сохранении дисциплины.", "Есть высокий шанс достижения $2M за 12–18 месяцев при системной работе и контроле ключевых метрик." ) ) ) -> #DIV/0!
A26: Анализ проведён | B26: Марина Рахимжанова, GTM-архитектор
